### 9. Exception Handling

#### Basic Exception Handling

Groovy's exception handling is similar to Java, using `try`, `catch`, and `finally` blocks.

```groovy
try {
    int result = 10 / 0
    println "Result: $result"
} catch (ArithmeticException e) {
    println "Caught an ArithmeticException: ${e.message}"
} finally {
    println "This will always execute"
}
```

#### Multiple Catch Blocks

You can catch multiple exceptions in a single `try` block.

```groovy
try {
    int[] arr = [1, 2, 3]
    println arr[5]
} catch (ArrayIndexOutOfBoundsException e) {
    println "Caught an ArrayIndexOutOfBoundsException: ${e.message}"
} catch (Exception e) {
    println "Caught a generic exception: ${e.message}"
}
```

#### Nested Exception Handling

Exception handling can be nested within other `try` blocks.

```groovy
try {
    try {
        int result = 10 / 0
    } catch (ArithmeticException e) {
        println "Inner catch: ArithmeticException: ${e.message}"
        throw new RuntimeException("Wrapped Exception", e)
    }
} catch (RuntimeException e) {
    println "Outer catch: RuntimeException: ${e.message}"
    e.printStackTrace()
}
```

#### Custom Exceptions

You can define your own custom exception classes.

```groovy
class CustomException extends Exception {
    CustomException(String message) {
        super(message)
    }
}

try {
    throw new CustomException("This is a custom exception")
} catch (CustomException e) {
    println "Caught a CustomException: ${e.message}"
}
```

#### Exception Propagation

Exceptions can be propagated up the call stack.

```groovy
def divide(int a, int b) {
    if (b == 0) {
        throw new ArithmeticException("Division by zero")
    }
    return a / b
}

try {
    println divide(10, 0)
} catch (ArithmeticException e) {
    println "Caught an ArithmeticException: ${e.message}"
}
```

#### Using `throw` Keyword

The `throw` keyword is used to explicitly throw an exception.

```groovy
def checkAge(int age) {
    if (age < 18) {
        throw new IllegalArgumentException("Age must be 18 or older")
    }
    println "Age is valid"
}

try {
    checkAge(16)
} catch (IllegalArgumentException e) {
    println "Caught an IllegalArgumentException: ${e.message}"
}
```

#### Rethrowing Exceptions

You can catch and then rethrow exceptions.

```groovy
try {
    try {
        throw new IOException("IO error")
    } catch (IOException e) {
        println "Caught IOException: ${e.message}"
        throw e  // Rethrow the exception
    }
} catch (IOException e) {
    println "Caught rethrown IOException: ${e.message}"
}
```

#### Using `assert` for Simple Exception Handling

Groovy's `assert` can be used for simple checks.

```groovy
def divide(int a, int b) {
    assert b != 0 : "Divider cannot be zero"
    a / b
}

try {
    println divide(10, 0)
} catch (AssertionError e) {
    println "Caught AssertionError: ${e.message}"
}
```




