### 9. Exception Handling in Groovy

#### Overview
Exception handling is a crucial part of any programming language. 

Groovy, being a superset of Java, uses the same exception handling mechanisms as Java but with some Groovy-specific enhancements. 

Here, we will explore how to handle exceptions in Groovy with various examples.

#### Basic Exception Handling

Groovy's exception handling is similar to Java, using `try`, `catch`, and `finally` blocks.

```groovy
try {
    int result = 10 / 0
    println "Result: $result"
} catch (ArithmeticException e) {
    println "Caught an ArithmeticException: ${e.message}"
} finally {
    println "This will always execute"
}
```

#### Multiple Catch Blocks

You can catch multiple exceptions in a single `try` block.

```groovy
try {
    int[] arr = [1, 2, 3]
    println arr[5]
} catch (ArrayIndexOutOfBoundsException e) {
    println "Caught an ArrayIndexOutOfBoundsException: ${e.message}"
} catch (Exception e) {
    println "Caught a generic exception: ${e.message}"
}
```

#### Nested Exception Handling

Exception handling can be nested within other `try` blocks.

```groovy
try {
    try {
        int result = 10 / 0
    } catch (ArithmeticException e) {
        println "Inner catch: ArithmeticException: ${e.message}"
        throw new RuntimeException("Wrapped Exception", e)
    }
} catch (RuntimeException e) {
    println "Outer catch: RuntimeException: ${e.message}"
    e.printStackTrace()
}
```

#### Custom Exceptions

You can define your own custom exception classes.

```groovy
class CustomException extends Exception {
    CustomException(String message) {
        super(message)
    }
}

try {
    throw new CustomException("This is a custom exception")
} catch (CustomException e) {
    println "Caught a CustomException: ${e.message}"
}
```

#### Exception Propagation

Exceptions can be propagated up the call stack.

```groovy
def divide(int a, int b) {
    if (b == 0) {
        throw new ArithmeticException("Division by zero")
    }
    return a / b
}

try {
    println divide(10, 0)
} catch (ArithmeticException e) {
    println "Caught an ArithmeticException: ${e.message}"
}
```

#### Using `throw` Keyword

The `throw` keyword is used to explicitly throw an exception.

```groovy
def checkAge(int age) {
    if (age < 18) {
        throw new IllegalArgumentException("Age must be 18 or older")
    }
    println "Age is valid"
}

try {
    checkAge(16)
} catch (IllegalArgumentException e) {
    println "Caught an IllegalArgumentException: ${e.message}"
}
```

#### Rethrowing Exceptions

You can catch and then rethrow exceptions.

```groovy
try {
    try {
        throw new IOException("IO error")
    } catch (IOException e) {
        println "Caught IOException: ${e.message}"
        throw e  // Rethrow the exception
    }
} catch (IOException e) {
    println "Caught rethrown IOException: ${e.message}"
}
```

#### Using `assert` for Simple Exception Handling

Groovy's `assert` can be used for simple checks.

```groovy
def divide(int a, int b) {
    assert b != 0 : "Divider cannot be zero"
    a / b
}

try {
    println divide(10, 0)
} catch (AssertionError e) {
    println "Caught AssertionError: ${e.message}"
}
```


#### Groovy Exception Handling More Examples

1. **Basic Try-Catch Block**

    ```groovy
    try {
        int result = 10 / 0
    } catch (ArithmeticException e) {
        println "Caught an arithmetic exception: ${e.message}"
    }
    ```

    Explanation: This script catches an `ArithmeticException` when attempting to divide by zero and prints the exception message.

2. **Multiple Catch Blocks**

    ```groovy
    try {
        String s = null
        s.length()
    } catch (NullPointerException e) {
        println "Caught a NullPointerException"
    } catch (Exception e) {
        println "Caught a generic exception"
    }
    ```

    Explanation: This script catches a `NullPointerException` specifically, but also has a catch block for any other exceptions.

3. **Finally Block**

    ```groovy
    try {
        int[] arr = [1, 2, 3]
        println arr[5]
    } catch (ArrayIndexOutOfBoundsException e) {
        println "Caught an ArrayIndexOutOfBoundsException"
    } finally {
        println "This is the finally block, executed regardless of an exception."
    }
    ```

    Explanation: This script demonstrates the use of a `finally` block which is executed whether an exception is thrown or not.

4. **Try-With-Resources**

    ```groovy
    def file = new File('example.txt')
    file.withReader { reader ->
        try {
            println reader.readLine()
        } catch (IOException e) {
            println "Caught an IOException: ${e.message}"
        }
    }
    ```

    Explanation: This script uses the Groovy's `withReader` method to automatically close the resource, demonstrating try-with-resources style.

5. **Throwing Exceptions**

    ```groovy
    def riskyMethod() {
        throw new IllegalStateException("Something went wrong")
    }

    try {
        riskyMethod()
    } catch (IllegalStateException e) {
        println "Caught an IllegalStateException: ${e.message}"
    }
    ```

    Explanation: This script defines a method that throws an `IllegalStateException` and handles it in a try-catch block.

6. **Custom Exception Class**

    ```groovy
    class CustomException extends Exception {
        CustomException(String message) {
            super(message)
        }
    }

    try {
        throw new CustomException("Custom error occurred")
    } catch (CustomException e) {
        println "Caught a CustomException: ${e.message}"
    }
    ```

    Explanation: This script defines a custom exception class and demonstrates how to throw and catch it.

7. **Catching Multiple Exceptions in One Block**

    ```groovy
    try {
        int[] arr = [1, 2, 3]
        println arr[5]
    } catch (NullPointerException | ArrayIndexOutOfBoundsException e) {
        println "Caught a NullPointerException or ArrayIndexOutOfBoundsException: ${e.message}"
    }
    ```

    Explanation: This script demonstrates catching multiple exception types in a single catch block using Groovy's syntax.

8. **Re-throwing Exceptions**

    ```groovy
    def handleException() {
        try {
            int result = 10 / 0
        } catch (ArithmeticException e) {
            println "Handling exception and re-throwing"
            throw e
        }
    }

    try {
        handleException()
    } catch (ArithmeticException e) {
        println "Caught re-thrown exception: ${e.message}"
    }
    ```

    Explanation: This script shows how to handle an exception and then re-throw it to be caught by an outer try-catch block.

9. **Exception Handling in Closures**

    ```groovy
    def safeDivide = { a, b ->
        try {
            a / b
        } catch (ArithmeticException e) {
            println "Cannot divide by zero"
            return null
        }
    }

    println safeDivide(10, 2)
    println safeDivide(10, 0)
    ```

    Explanation: This script handles exceptions within a Groovy closure.

10. **Using assert for Exception Handling**

    ```groovy
    try {
        assert 1 == 2 : "Assertion failed!"
    } catch (AssertionError e) {
        println "Caught an AssertionError: ${e.message}"
    }
    ```

    Explanation: This script uses an `assert` statement to check a condition and throws an `AssertionError` if the condition is false.

11. **Handling Checked Exceptions**

    ```groovy
    def readFile(String path) throws IOException {
        new File(path).text
    }

    try {
        println readFile('nonexistent.txt')
    } catch (IOException e) {
        println "Caught an IOException: ${e.message}"
    }
    ```

    Explanation: This script demonstrates handling checked exceptions by defining a method that throws an `IOException`.

12. **Logging Exceptions**

    ```groovy
    import groovy.util.logging.Slf4j

    @Slf4j
    class ExceptionLogger {
        def methodThatFails() {
            try {
                throw new Exception("An error occurred")
            } catch (Exception e) {
                log.error "Caught an exception", e
            }
        }
    }

    new ExceptionLogger().methodThatFails()
    ```

    Explanation: This script shows how to log exceptions using Groovy's `@Slf4j` annotation.

13. **Handling Exceptions in Groovy Scripts**

    ```groovy
    try {
        def result = '5' as int
    } catch (ClassCastException e) {
        println "Caught a ClassCastException: ${e.message}"
    }
    ```

    Explanation: This script demonstrates handling exceptions that may occur during type casting in Groovy scripts.

14. **Exception Handling in Asynchronous Code**

    ```groovy
    def asyncOperation = { ->
        try {
            throw new Exception("Async error")
        } catch (Exception e) {
            println "Caught an exception in async operation: ${e.message}"
        }
    }

    Thread.start(asyncOperation)
    ```

    Explanation: This script shows how to handle exceptions in an asynchronous operation using a closure.

15. **Handling Nested Exceptions**

    ```groovy
    try {
        try {
            int result = 10 / 0
        } catch (ArithmeticException e) {
            println "Caught an ArithmeticException"
            throw new RuntimeException("Wrapper exception", e)
        }
    } catch (RuntimeException e) {
        println "Caught a RuntimeException: ${e.message}"
        println "Caused by: ${e.cause}"
    }
    ```

    Explanation: This script demonstrates how to handle nested exceptions and access the original cause.

16. **Using @Catch Annotation in Spock Framework**

    ```groovy
    import spock.lang.Specification

    class ExceptionSpec extends Specification {
        @Catch(ArithmeticException)
        def 'should handle exception'() {
            when:
            int result = 10 / 0

            then:
            def e = thrown()
            e.message == '/ by zero'
        }
    }
    ```

    Explanation: This script shows how to handle exceptions in tests using the `@Catch` annotation in the Spock framework.

17. **Custom Exception Messages**

    ```groovy
    def validateAge(int age) {
        if (age < 18) {
            throw new IllegalArgumentException("Age must be 18 or older")
        }
    }

    try {
        validateAge(16)
    } catch (IllegalArgumentException e) {
        println "Caught an IllegalArgumentException: ${e.message}"
    }
    ```

    Explanation: This script shows how to throw an exception with a custom message and catch it.

18. **Handling Exceptions in Stream Processing**

    ```groovy
    def data = ['1', '2', 'a', '4']

    data.each {
        try {
            int value = it as int
            println value
        } catch (NumberFormatException e) {
            println "Caught a NumberFormatException: ${e.message}"
        }
    }
    ```

    Explanation: This script demonstrates handling exceptions during stream processing of a collection.

19. **Handling Exceptions in Map Operations**

    ```groovy
    def map = [key1: 'value1', key2: 'value2']

    try {
        def value = map['key3'].toUpperCase()
    } catch (NullPointerException e) {
        println "Caught a NullPointerException: ${e.message}"
    }
    ```

    Explanation: This script shows how to handle exceptions when operating on maps in Groovy.

20. **Exception Handling with Optional**

    ```groovy
    def safeDivide(a, b) {
        try {
            return Optional.of(a / b)
        } catch (ArithmeticException e) {
            return Optional.empty()
        }
    }

    println safeDivide(10, 2).orElse("Division failed")
    println safeDivide(10, 0).orElse("Division failed")
    ```

    Explanation: This script demonstrates using `Optional` to handle exceptions and provide a fallback value.

#### Conclusion

Exception handling in Groovy is both flexible and powerful, allowing developers to manage errors and unexpected conditions gracefully. 
These examples cover a broad range of scenarios, providing a solid foundation for effectively handling exceptions in your Groovy applications.


